[2018-01-07 10:27:22 +0000] [1] [DEBUG] Current configuration:
  config: ./conf/gunicorn_config.py
  bind: ['0.0.0.0:8080']
  backlog: 2048
  workers: 3
  worker_class: sync
  threads: 1
  worker_connections: 1000
  max_requests: 0
  max_requests_jitter: 0
  timeout: 30
  graceful_timeout: 30
  keepalive: 2
  limit_request_line: 4094
  limit_request_fields: 100
  limit_request_field_size: 8190
  reload: False
  reload_engine: auto
  spew: False
  check_config: False
  preload_app: False
  sendfile: None
  chdir: /app
  daemon: False
  raw_env: []
  pidfile: None
  worker_tmp_dir: None
  user: 0
  group: 0
  umask: 0
  initgroups: False
  tmp_upload_dir: None
  secure_scheme_headers: {'X-FORWARDED-PROTOCOL': 'ssl', 'X-FORWARDED-PROTO': 'https', 'X-FORWARDED-SSL': 'on'}
  forwarded_allow_ips: ['127.0.0.1']
  accesslog: -
  access_log_format: %(h)s %(l)s %(u)s %(t)s "%(r)s" %(s)s %(b)s "%(f)s" "%(a)s"
  errorlog: -
  loglevel: debug
  capture_output: True
  logger_class: gunicorn.glogging.Logger
  logconfig: None
  syslog_addr: udp://localhost:514
  syslog: False
  syslog_prefix: None
  syslog_facility: user
  enable_stdio_inheritance: True
  statsd_host: None
  statsd_prefix: 
  proc_name: None
  default_proc_name: src:app
  pythonpath: None
  paste: None
  on_starting: <function OnStarting.on_starting at 0x7f635f403d08>
  on_reload: <function OnReload.on_reload at 0x7f635f403ea0>
  when_ready: <function WhenReady.when_ready at 0x7f635f40c0d0>
  pre_fork: <function Prefork.pre_fork at 0x7f635f40c268>
  post_fork: <function Postfork.post_fork at 0x7f635f40c400>
  post_worker_init: <function PostWorkerInit.post_worker_init at 0x7f635f40c598>
  worker_int: <function WorkerInt.worker_int at 0x7f635f40c730>
  worker_abort: <function WorkerAbort.worker_abort at 0x7f635f40c8c8>
  pre_exec: <function PreExec.pre_exec at 0x7f635f40ca60>
  pre_request: <function PreRequest.pre_request at 0x7f635f40cbf8>
  post_request: <function PostRequest.post_request at 0x7f635f40cd08>
  child_exit: <function ChildExit.child_exit at 0x7f635f40cea0>
  worker_exit: <function WorkerExit.worker_exit at 0x7f635f1750d0>
  nworkers_changed: <function NumWorkersChanged.nworkers_changed at 0x7f635f175268>
  on_exit: <function OnExit.on_exit at 0x7f635f175400>
  proxy_protocol: False
  proxy_allow_ips: ['127.0.0.1']
  keyfile: None
  certfile: None
  ssl_version: 2
  cert_reqs: 0
  ca_certs: None
  suppress_ragged_eofs: True
  do_handshake_on_connect: False
  ciphers: TLSv1
  raw_paste_global_conf: []
[2018-01-07 10:27:22 +0000] [1] [INFO] Starting gunicorn 19.7.1
[2018-01-07 10:27:22 +0000] [1] [DEBUG] Arbiter booted
[2018-01-07 10:27:22 +0000] [1] [INFO] Listening at: http://0.0.0.0:8080 (1)
[2018-01-07 10:27:22 +0000] [1] [INFO] Using worker: sync
[2018-01-07 10:27:22 +0000] [7] [INFO] Booting worker with pid: 7
[2018-01-07 10:27:22 +0000] [8] [INFO] Booting worker with pid: 8
[2018-01-07 10:27:22 +0000] [9] [INFO] Booting worker with pid: 9
[2018-01-07 10:27:22 +0000] [1] [DEBUG] 3 workers
[2018-01-07 10:28:39 +0000] [8] [DEBUG] GET /image
[2018-01-07 10:28:39,403] ERROR in app: Exception on /image [GET]
Traceback (most recent call last):
  File "/usr/local/lib/python3.6/site-packages/flask/app.py", line 1982, in wsgi_app
    response = self.full_dispatch_request()
  File "/usr/local/lib/python3.6/site-packages/flask/app.py", line 1614, in full_dispatch_request
    rv = self.handle_user_exception(e)
  File "/usr/local/lib/python3.6/site-packages/flask/app.py", line 1517, in handle_user_exception
    reraise(exc_type, exc_value, tb)
  File "/usr/local/lib/python3.6/site-packages/flask/_compat.py", line 33, in reraise
    raise value
  File "/usr/local/lib/python3.6/site-packages/flask/app.py", line 1612, in full_dispatch_request
    rv = self.dispatch_request()
  File "/usr/local/lib/python3.6/site-packages/flask/app.py", line 1598, in dispatch_request
    return self.view_functions[rule.endpoint](**req.view_args)
  File "/app/src/server.py", line 62, in display_image
    return send_file("SimpleImage.jpeg",mimetype='image/gif')
  File "/usr/local/lib/python3.6/site-packages/flask/helpers.py", line 549, in send_file
    file = open(filename, 'rb')
FileNotFoundError: [Errno 2] No such file or directory: '/app/src/SimpleImage.jpeg'
10.2.94.41 - - [07/Jan/2018:10:28:39 +0000] "GET /image HTTP/1.0" 500 291 "-" "Mozilla/5.0 (Windows NT 10.0; Win64; x64) AppleWebKit/537.36 (KHTML, like Gecko) Chrome/63.0.3239.132 Safari/537.36"
[2018-01-07 10:29:51 +0000] [7] [DEBUG] GET /image
[2018-01-07 10:29:51,432] ERROR in app: Exception on /image [GET]
Traceback (most recent call last):
  File "/usr/local/lib/python3.6/site-packages/flask/app.py", line 1982, in wsgi_app
    response = self.full_dispatch_request()
  File "/usr/local/lib/python3.6/site-packages/flask/app.py", line 1614, in full_dispatch_request
    rv = self.handle_user_exception(e)
  File "/usr/local/lib/python3.6/site-packages/flask/app.py", line 1517, in handle_user_exception
    reraise(exc_type, exc_value, tb)
  File "/usr/local/lib/python3.6/site-packages/flask/_compat.py", line 33, in reraise
    raise value
  File "/usr/local/lib/python3.6/site-packages/flask/app.py", line 1612, in full_dispatch_request
    rv = self.dispatch_request()
  File "/usr/local/lib/python3.6/site-packages/flask/app.py", line 1598, in dispatch_request
    return self.view_functions[rule.endpoint](**req.view_args)
  File "/app/src/server.py", line 62, in display_image
    return send_file("SimpleImage.jpeg",mimetype='image/gif')
  File "/usr/local/lib/python3.6/site-packages/flask/helpers.py", line 549, in send_file
    file = open(filename, 'rb')
FileNotFoundError: [Errno 2] No such file or directory: '/app/src/SimpleImage.jpeg'
10.2.94.41 - - [07/Jan/2018:10:29:51 +0000] "GET /image HTTP/1.0" 500 291 "-" "Mozilla/5.0 (Windows NT 10.0; Win64; x64) AppleWebKit/537.36 (KHTML, like Gecko) Chrome/63.0.3239.132 Safari/537.36"
[2018-01-07 10:29:56 +0000] [9] [DEBUG] GET /.git/config
10.2.94.41 - - [07/Jan/2018:10:29:56 +0000] "GET /.git/config HTTP/1.0" 404 233 "http://app.carrier19.hasura-app.io/.git/config" "Go-http-client/1.1"
[2018-01-07 10:29:58 +0000] [8] [DEBUG] GET /html
10.2.94.41 - - [07/Jan/2018:10:29:58 +0000] "GET /html HTTP/1.0" 200 161 "-" "Mozilla/5.0 (Windows NT 10.0; Win64; x64) AppleWebKit/537.36 (KHTML, like Gecko) Chrome/63.0.3239.132 Safari/537.36"
[2018-01-07 10:30:06 +0000] [9] [DEBUG] GET /image
[2018-01-07 10:30:06,612] ERROR in app: Exception on /image [GET]
Traceback (most recent call last):
  File "/usr/local/lib/python3.6/site-packages/flask/app.py", line 1982, in wsgi_app
    response = self.full_dispatch_request()
  File "/usr/local/lib/python3.6/site-packages/flask/app.py", line 1614, in full_dispatch_request
    rv = self.handle_user_exception(e)
  File "/usr/local/lib/python3.6/site-packages/flask/app.py", line 1517, in handle_user_exception
    reraise(exc_type, exc_value, tb)
  File "/usr/local/lib/python3.6/site-packages/flask/_compat.py", line 33, in reraise
    raise value
  File "/usr/local/lib/python3.6/site-packages/flask/app.py", line 1612, in full_dispatch_request
    rv = self.dispatch_request()
  File "/usr/local/lib/python3.6/site-packages/flask/app.py", line 1598, in dispatch_request
    return self.view_functions[rule.endpoint](**req.view_args)
  File "/app/src/server.py", line 62, in display_image
    return send_file("SimpleImage.jpeg",mimetype='image/gif')
  File "/usr/local/lib/python3.6/site-packages/flask/helpers.py", line 549, in send_file
    file = open(filename, 'rb')
FileNotFoundError: [Errno 2] No such file or directory: '/app/src/SimpleImage.jpeg'
10.2.94.41 - - [07/Jan/2018:10:30:06 +0000] "GET /image HTTP/1.0" 500 291 "-" "Mozilla/5.0 (Windows NT 10.0; Win64; x64) AppleWebKit/537.36 (KHTML, like Gecko) Chrome/63.0.3239.132 Safari/537.36"
